Workbook
Name DstStart: 'League Config'!$B$17
Name GateSize: 'League Config'!$B$19
Name KStart: 'League Config'!$B$18
Name NDst: 'League Config'!$B$22
Name NSkill: 'League Config'!$B$21

Sheet Draft Board
A1: Draft Board: go in order, mark every pick in the Pick column. Marked rows cross out. | P1: Freeze adjustments once the draft starts: picks attach to board slots, so do not edit Manual Adjustments mid-draft.
A2: Overall | B2: Pos | C2: Pos Rank | D2: Player / Defense | E2: Adj Rating | F2: Tier | G2: Draft Score | H2: Market ADP | I2: Draft Edge | J2: Pick | K2: Avail Rank | L2: 2026 Expectation | M2: Src | N2: Bye
A3: 1 | B3: =INDEX('Draft Engine'!$A$3:$A$232,$M3) -> WR | C3: =INDEX('Draft Engine'!$F$3:$F$232,$M3) -> 1 | D3: =INDEX('Draft Engine'!$B$3:$B$232,$M3) -> Puka Nacua | E3: =INDEX('Draft Engine'!$E$3:$E$232,$M3) -> 98.4859 | F3: =IF($E3>=95,"ELITE",IF($E3>=90,"TIER 1",IF($E3>=85,"TIER 2",IF($E3>=80,"TIER 3",IF($E3>=75,"TIER 4",IF($E3>=70,"TIER 5",IF($E3>=65,"TIER 6","TIER 7"))))))) -> ELITE | G3: =INDEX('Draft Engine'!$N$3:$N$232,$M3) -> 99.167245 | H3: =INDEX('Draft Engine'!$R$3:$R$232,$M3) -> 2.9 | I3: =INDEX('Draft Engine'!$S$3:$S$232,$M3) -> 1.9 | K3: =INDEX('Draft Engine'!$Z$3:$Z$232,$M3) -> 1 | L3: =INDEX('LIVE SOURCE'!$H$3:$H$232,$M3) -> Elite WR1 and first-round caliber target with overall WR1 upside. | M3: =MATCH($A3,'Draft Engine'!$Q$3:$Q$232,0) -> 86 | N3: =INDEX('LIVE SOURCE'!$L$3:$L$232,$M3) -> 11
A4: 2 | B4: =INDEX('Draft Engine'!$A$3:$A$232,$M4) -> RB | C4: =INDEX('Draft Engine'!$F$3:$F$232,$M4) -> 1 | D4: =INDEX('Draft Engine'!$B$3:$B$232,$M4) -> Bijan Robinson | E4: =INDEX('Draft Engine'!$E$3:$E$232,$M4) -> 97.3673 | F4: =IF($E4>=95,"ELITE",IF($E4>=90,"TIER 1",IF($E4>=85,"TIER 2",IF($E4>=80,"TIER 3",IF($E4>=75,"TIER 4",IF($E4>=70,"TIER 5",IF($E4>=65,"TIER 6","TIER 7"))))))) -> ELITE | G4: =INDEX('Draft Engine'!$N$3:$N$232,$M4) -> 98.552015 | H4: =INDEX('Draft Engine'!$R$3:$R$232,$M4) -> 1.8 | I4: =INDEX('Draft Engine'!$S$3:$S$232,$M4) -> -0.2 | K4: =INDEX('Draft Engine'!$Z$3:$Z$232,$M4) -> 2 | L4: =INDEX('LIVE SOURCE'!$H$3:$H$232,$M4) -> Elite RB1 and first-round roster anchor with league-winning ceiling. | M4: =MATCH($A4,'Draft Engine'!$Q$3:$Q$232,0) -> 33 | N4: =INDEX('LIVE SOURCE'!$L$3:$L$232,$M4) -> 11
A5: 3 | B5: =INDEX('Draft Engine'!$A$3:$A$232,$M5) -> WR | C5: =INDEX('Draft Engine'!$F$3:$F$232,$M5) -> 2 | D5: =INDEX('Draft Engine'!$B$3:$B$232,$M5) -> Ja'Marr Chase | E5: =INDEX('Draft Engine'!$E$3:$E$232,$M5) -> 96.7323 | F5: =IF($E5>=95,"ELITE",IF($E5>=90,"TIER 1",IF($E5>=85,"TIER 2",IF($E5>=80,"TIER 3",IF($E5>=75,"TIER 4",IF($E5>=70,"TIER 5",IF($E5>=65,"TIER 6","TIER 7"))))))) -> ELITE | G5: =INDEX('Draft Engine'!$N$3:$N$232,$M5) -> 98.202765 | H5: =INDEX('Draft Engine'!$R$3:$R$232,$M5) -> 3.9 | I5: =INDEX('Draft Engine'!$S$3:$S$232,$M5) -> 0.9 | K5: =INDEX('Draft Engine'!$Z$3:$Z$232,$M5) -> 3 | L5: =INDEX('LIVE SOURCE'!$H$3:$H$232,$M5) -> Elite WR1 and first-round caliber target with overall WR1 upside. | M5: =MATCH($A5,'Draft Engine'!$Q$3:$Q$232,0) -> 85 | N5: =INDEX('LIVE SOURCE'!$L$3:$L$232,$M5) -> 6
A6: 4 | B6: =INDEX('Draft Engine'!$A$3:$A$232,$M6) -> RB | C6: =INDEX('Draft Engine'!$F$3:$F$232,$M6) -> 2 | D6: =INDEX('Draft Engine'!$B$3:$B$232,$M6) -> Jahmyr Gibbs | E6: =INDEX('Draft Engine'!$E$3:$E$232,$M6) -> 96.3323 | F6: =IF($E6>=95,"ELITE",IF($E6>=90,"TIER 1",IF($E6>=85,"TIER 2",IF($E6>=80,"TIER 3",IF($E6>=75,"TIER 4",IF($E6>=70,"TIER 5",IF($E6>=65,"TIER 6","TIER 7"))))))) -> ELITE | G6: =INDEX('Draft Engine'!$N$3:$N$232,$M6) -> 97.982765 | H6: =INDEX('Draft Engine'!$R$3:$R$232,$M6) -> 1.8 | I6: =INDEX('Draft Engine'!$S$3:$S$232,$M6) -> -2.2 | K6: =INDEX('Draft Engine'!$Z$3:$Z$232,$M6) -> 4 | L6: =INDEX('LIVE SOURCE'!$H$3:$H$232,$M6) -> Elite RB1 and first-round roster anchor with league-winning ceiling. | M6: =MATCH($A6,'Draft Engine'!$Q$3:$Q$232,0) -> 34 | N6: =INDEX('LIVE SOURCE'!$L$3:$L$232,$M6) -> 6
A7: 5 | B7: =INDEX('Draft Engine'!$A$3:$A$232,$M7) -> RB | C7: =INDEX('Draft Engine'!$F$3:$F$232,$M7) -> 3 | D7: =INDEX('Draft Engine'!$B$3:$B$232,$M7) -> Christian McCaffrey | E7: =INDEX('Draft Engine'!$E$3:$E$232,$M7) -> 94.2447 | F7: =IF($E7>=95,"ELITE",IF($E7>=90,"TIER 1",IF($E7>=85,"TIER 2",IF($E7>=80,"TIER 3",IF($E7>=75,"TIER 4",IF($E7>=70,"TIER 5",IF($E7>=65,"TIER 6","TIER 7"))))))) -> TIER 1 | G7: =INDEX('Draft Engine'!$N$3:$N$232,$M7) -> 96.834585 | H7: =INDEX('Draft Engine'!$R$3:$R$232,$M7) -> 5.8 | I7: =INDEX('Draft Engine'!$S$3:$S$232,$M7) -> 0.8 | K7: =INDEX('Draft Engine'!$Z$3:$Z$232,$M7) -> 5 | L7: =INDEX('LIVE SOURCE'!$H$3:$H$232,$M7) -> Elite RB1 and first-round roster anchor with league-winning ceiling. | M7: =MATCH($A7,'Draft Engine'!$Q$3:$Q$232,0) -> 35 | N7: =INDEX('LIVE SOURCE'!$L$3:$L$232,$M7) -> 8
A8: 6 | B8: =INDEX('Draft Engine'!$A$3:$A$232,$M8) -> WR | C8: =INDEX('Draft Engine'!$F$3:$F$232,$M8) -> 3 | D8: =INDEX('Draft Engine'!$B$3:$B$232,$M8) -> Jaxon Smith-Njigba | E8: =INDEX('Draft Engine'!$E$3:$E$232,$M8) -> 94.0799 | F8: =IF($E8>=95,"ELITE",IF($E8>=90,"TIER 1",IF($E8>=85,"TIER 2",IF($E8>=80,"TIER 3",IF($E8>=75,"TIER 4",IF($E8>=70,"TIER 5",IF($E8>=65,"TIER 6","TIER 7"))))))) -> TIER 1 | G8: =INDEX('Draft Engine'!$N$3:$N$232,$M8) -> 96.743945 | H8: =INDEX('Draft Engine'!$R$3:$R$232,$M8) -> 5.7 | I8: =INDEX('Draft Engine'!$S$3:$S$232,$M8) -> -0.3 | K8: =INDEX('Draft Engine'!$Z$3:$Z$232,$M8) -> 6 | L8: =INDEX('LIVE SOURCE'!$H$3:$H$232,$M8) -> Elite WR1 and first-round caliber target with overall WR1 upside. | M8: =MATCH($A8,'Draft Engine'!$Q$3:$Q$232,0) -> 87 | N8: =INDEX('LIVE SOURCE'!$L$3:$L$232,$M8) -> 11
A9: 7 | B9: =INDEX('Draft Engine'!$A$3:$A$232,$M9) -> WR | C9: =INDEX('Draft Engine'!$F$3:$F$232,$M9) -> 4 | D9: =INDEX('Draft Engine'!$B$3:$B$232,$M9) -> Amon-Ra St. Brown | E9: =INDEX('Draft Engine'!$E$3:$E$232,$M9) -> 93.2639 | F9: =IF($E9>=95,"ELITE",IF($E9>=90,"TIER 1",IF($E9>=85,"TIER 2",IF($E9>=80,"TIER 3",IF($E9>=75,"TIER 4",IF($E9>=70,"TIER 5",IF($E9>=65,"TIER 6","TIER 7"))))))) -> TIER 1 | G9: =INDEX('Draft Engine'!$N$3:$N$232,$M9) -> 96.127145 | H9: =INDEX('Draft Engine'!$R$3:$R$232,$M9) -> 7 | I9: =INDEX('Draft Engine'!$S$3:$S$232,$M9) -> 0 | K9: =INDEX('Draft Engine'!$Z$3:$Z$232,$M9) -> 7 | L9: =INDEX('LIVE SOURCE'!$H$3:$H$232,$M9) -> Elite WR1 and first-round caliber target with overall WR1 upside. | M9: =MATCH($A9,'Draft Engine'!$Q$3:$Q$232,0) -> 88 | N9: =INDEX('LIVE SOURCE'!$L$3:$L$232,$M9) -> 6
A10: 8 | B10: =INDEX('Draft Engine'!$A$3:$A$232,$M10) -> RB | C10: =INDEX('Draft Engine'!$F$3:$F$232,$M10) -> 4 | D10: =INDEX('Draft Engine'!$B$3:$B$232,$M10) -> Jonathan Taylor | E10: =INDEX('Draft Engine'!$E$3:$E$232,$M10) -> 92.147 | F10: =IF($E10>=95,"ELITE",IF($E10>=90,"TIER 1",IF($E10>=85,"TIER 2",IF($E10>=80,"TIER 3",IF($E10>=75,"TIER 4",IF($E10>=70,"TIER 5",IF($E10>=65,"TIER 6","TIER 7"))))))) -> TIER 1 | G10: =INDEX('Draft Engine'!$N$3:$N$232,$M10) -> 94.72085 | H10: =INDEX('Draft Engine'!$R$3:$R$232,$M10) -> 7.4 | I10: =INDEX('Draft Engine'!$S$3:$S$232,$M10) -> -0.6 | K10: =INDEX('Draft Engine'!$Z$3:$Z$232,$M10) -> 8 | L10: =INDEX('LIVE SOURCE'!$H$3:$H$232,$M10) -> Elite RB1 and first-round roster anchor with league-winning ceiling. | M10: =MATCH($A10,'Draft Engine'!$Q$3:$Q$232,0) -> 36 | N10: =INDEX('LIVE SOURCE'!$L$3:$L$232,$M10) -> 13
A11: 9 | B11: =INDEX('Draft Engine'!$A$3:$A$232,$M11) -> WR | C11: =INDEX('Draft Engine'!$F$3:$F$232,$M11) -> 5 | D11: =INDEX('Draft Engine'!$B$3:$B$232,$M11) -> Nico Collins | E11: =INDEX('Draft Engine'!$E$3:$E$232,$M11) -> 91.4925 | F11: =IF($E11>=95,"ELITE",IF($E11>=90,"TIER 1",IF($E11>=85,"TIER 2",IF($E11>=80,"TIER 3",IF($E11>=75,"TIER 4",IF($E11>=70,"TIER 5",IF($E11>=65,"TIER 6","TIER 7"))))))) -> TIER 1 | G11: =INDEX('Draft Engine'!$N$3:$N$232,$M11) -> 93.820875 | H11: =INDEX('Draft Engine'!$R$3:$R$232,$M11) -> 23.8 | I11: =INDEX('Draft Engine'!$S$3:$S$232,$M11) -> 14.8 | K11: =INDEX('Draft Engine'!$Z$3:$Z$232,$M11) -> 9 | L11: =INDEX('LIVE SOURCE'!$H$3:$H$232,$M11) -> Elite WR1 and first-round caliber target with overall WR1 upside. | M11: =MATCH($A11,'Draft Engine'!$Q$3:$Q$232,0) -> 94 | N11: =INDEX('LIVE SOURCE'!$L$3:$L$232,$M11) -> 8
A12: 10 | B12: =INDEX('Draft Engine'!$A$3:$A$232,$M12) -> TE | C12: =INDEX('Draft Engine'!$F$3:$F$232,$M12) -> 1 | D12: =INDEX('Draft Engine'!$B$3:$B$232,$M12) -> Trey McBride | E12: =INDEX('Draft Engine'!$E$3:$E$232,$M12) -> 97.7371 | F12: =IF($E12>=95,"ELITE",IF($E12>=90,"TIER 1",IF($E12>=85,"TIER 2",IF($E12>=80,"TIER 3",IF($E12>=75,"TIER 4",IF($E12>=70,"TIER 5",IF($E12>=65,"TIER 6","TIER 7"))))))) -> ELITE | G12: =INDEX('Draft Engine'!$N$3:$N$232,$M12) -> 93.487405 | H12: =INDEX('Draft Engine'!$R$3:$R$232,$M12) -> 35.7 | I12: =INDEX('Draft Engine'!$S$3:$S$232,$M12) -> 25.7 | K12: =INDEX('Draft Engine'!$Z$3:$Z$232,$M12) -> 10 | L12: =INDEX('LIVE SOURCE'!$H$3:$H$232,$M12) -> Elite difference-making TE; positional advantage is the expectation. | M12: =MATCH($A12,'Draft Engine'!$Q$3:$Q$232,0) -> 159 | N12: =INDEX('LIVE SOURCE'!$L$3:$L$232,$M12) -> 14
A13: 11 | B13: =INDEX('Draft Engine'!$A$3:$A$232,$M13) -> RB | C13: =INDEX('Draft Engine'!$F$3:$F$232,$M13) -> 5 | D13: =INDEX('Draft Engine'!$B$3:$B$232,$M13) -> Jeremiyah Love | E13: =INDEX('Draft Engine'!$E$3:$E$232,$M13) -> 90.8659 | F13: =IF($E13>=95,"ELITE",IF($E13>=90,"TIER 1",IF($E13>=85,"TIER 2",IF($E13>=80,"TIER 3",IF($E13>=75,"TIER 4",IF($E13>=70,"TIER 5",IF($E13>=65,"TIER 6","TIER 7"))))))) -> TIER 1 | G13: =INDEX('Draft Engine'!$N$3:$N$232,$M13) -> 93.044245 | H13: =INDEX('Draft Engine'!$R$3:$R$232,$M13) -> 26.2 | I13: =INDEX('Draft Engine'!$S$3:$S$232,$M13) -> 15.2 | K13: =INDEX('Draft Engine'!$Z$3:$Z$232,$M13) -> 11 | L13: =INDEX('LIVE SOURCE'!$H$3:$H$232,$M13) -> Elite RB1 and first-round roster anchor with league-winning ceiling. | M13: =MATCH($A13,'Draft Engine'!$Q$3:$Q$232,0) -> 37 | N13: =INDEX('LIVE SOURCE'!$L$3:$L$232,$M13) -> 14
A14: 12 | B14: =INDEX('Draft Engine'!$A$3:$A$232,$M14) -> QB | C14: =INDEX('Draft Engine'!$F$3:$F$232,$M14) -> 1 | D14: =INDEX('Draft Engine'!$B$3:$B$232,$M14) -> Josh Allen | E14: =INDEX('Draft Engine'!$E$3:$E$232,$M14) -> 97.3099 | F14: =IF($E14>=95,"ELITE",IF($E14>=90,"TIER 1",IF($E14>=85,"TIER 2",IF($E14>=80,"TIER 3",IF($E14>=75,"TIER 4",IF($E14>=70,"TIER 5",IF($E14>=65,"TIER 6","TIER 7"))))))) -> ELITE | G14: =INDEX('Draft Engine'!$N$3:$N$232,$M14) -> 90.744445 | H14: =INDEX('Draft Engine'!$R$3:$R$232,$M14) -> 26.6 | I14: =INDEX('Draft Engine'!$S$3:$S$232,$M14) -> 14.6 | K14: =INDEX('Draft Engine'!$Z$3:$Z$232,$M14) -> 12 | L14: =INDEX('LIVE SOURCE'!$H$3:$H$232,$M14) -> Elite QB1; weekly top-5 expectation with overall QB1 upside. | M14: =MATCH($A14,'Draft Engine'!$Q$3:$Q$232,0) -> 1 | N14: =INDEX('LIVE SOURCE'!$L$3:$L$232,$M14) -> 7
... A232: 230 | B232: =INDEX('Draft Engine'!$A$3:$A$232,$M232) -> K | C232: =INDEX('Draft Engine'!$F$3:$F$232,$M232) -> 12 | D232: =INDEX('Draft Engine'!$B$3:$B$232,$M232) -> Evan McPherson | E232: =INDEX('Draft Engine'!$E$3:$E$232,$M232) -> 69.8 | F232: =IF($E232>=95,"ELITE",IF($E232>=90,"TIER 1",IF($E232>=85,"TIER 2",IF($E232>=80,"TIER 3",IF($E232>=75,"TIER 4",IF($E232>=70,"TIER 5",IF($E232>=65,"TIER 6","TIER 7"))))))) -> TIER 6 | G232: =INDEX('Draft Engine'!$N$3:$N$232,$M232) -> 36.006 | H232: =INDEX('Draft Engine'!$R$3:$R$232,$M232) -> 210 | I232: =INDEX('Draft Engine'!$S$3:$S$232,$M232) -> -20 | K232: =INDEX('Draft Engine'!$Z$3:$Z$232,$M232) -> 230 | L232: =INDEX('LIVE SOURCE'!$H$3:$H$232,$M232) -> Late-round kicker; treat as replaceable unless scoring strongly rewards distance. | M232: =MATCH($A232,'Draft Engine'!$Q$3:$Q$232,0) -> 198 | N232: =INDEX('LIVE SOURCE'!$L$3:$L$232,$M232) -> 6

Sheet League Config
A1: League Configuration (Editable)
A2: Blue cells are yours to edit. Everything downstream recalculates automatically.
A3: League Setting | B3: Value | C3: Notes | E3: Position | F3: Calc Repl Rank | G3: Override | H3: Effective Rank | I3: Replacement Points | J3: Scarcity Mult | K3: Pts Slope | L3: Pts Intercept
A4: Teams | B4: 10 | C4: League size. | E4: QB | F4: =ROUND($B$4*$B$6+$B$4*0.3,0) -> 13 | H4: =IF($G4="",$F4,$G4) -> 13 | I4: =ROUND(_xlfn.AGGREGATE(14,6,'Draft Engine'!$G$3:$G$232/('Draft Engine'!$A$3:$A$232=$E4),MIN($H4,COUNTIF('Draft Engine'!$A$3:$A$232,$E4))),1) -> 351.1 | J4: 1 | K4: 4.5 | L4: -30
A5: Scoring | B5: PPR | C5: Player model is PPR. | E5: RB | F5: =ROUND($B$4*$B$7+$B$4*$B$10*0.55+$B$4*0.6,0) -> 32 | H5: =IF($G5="",$F5,$G5) -> 32 | I5: =ROUND(_xlfn.AGGREGATE(14,6,'Draft Engine'!$G$3:$G$232/('Draft Engine'!$A$3:$A$232=$E5),MIN($H5,COUNTIF('Draft Engine'!$A$3:$A$232,$E5))),1) -> 239 | J5: 1.15 | K5: 4.2 | L5: -70
A6: Starting QB | B6: 1 | C6: Per team. | E6: WR | F6: =ROUND($B$4*$B$8+$B$4*$B$10*0.45+$B$4*0.8,0) -> 33 | H6: =IF($G6="",$F6,$G6) -> 33 | I6: =ROUND(_xlfn.AGGREGATE(14,6,'Draft Engine'!$G$3:$G$232/('Draft Engine'!$A$3:$A$232=$E6),MIN($H6,COUNTIF('Draft Engine'!$A$3:$A$232,$E6))),1) -> 239.3 | J6: 1.1 | K6: 4.2 | L6: -70
A7: Starting RB | B7: 2 | C7: Per team. | E7: TE | F7: =ROUND($B$4*$B$9+$B$4*0.3,0) -> 13 | H7: =IF($G7="",$F7,$G7) -> 13 | I7: =ROUND(_xlfn.AGGREGATE(14,6,'Draft Engine'!$G$3:$G$232/('Draft Engine'!$A$3:$A$232=$E7),MIN($H7,COUNTIF('Draft Engine'!$A$3:$A$232,$E7))),1) -> 179.7 | J7: 0.9 | K7: 3.5 | L7: -100
A8: Starting WR | B8: 2 | C8: Per team. | E8: K | F8: =ROUND($B$4*$B$11,0) -> 10 | H8: =IF($G8="",$F8,$G8) -> 10 | I8: =ROUND(_xlfn.AGGREGATE(14,6,'Draft Engine'!$G$3:$G$232/('Draft Engine'!$A$3:$A$232=$E8),MIN($H8,COUNTIF('Draft Engine'!$A$3:$A$232,$E8))),1) -> 108.4 | J8: 0.55 | K8: 2 | L8: -40
A9: Starting TE | B9: 1 | C9: Per team. | E9: DST | F9: =ROUND($B$4*$B$12,0) -> 10 | H9: =IF($G9="",$F9,$G9) -> 10 | I9: =ROUND(_xlfn.AGGREGATE(14,6,'Draft Engine'!$G$3:$G$232/('Draft Engine'!$A$3:$A$232=$E9),MIN($H9,COUNTIF('Draft Engine'!$A$3:$A$232,$E9))),1) -> 99.6 | J9: 0.5 | K9: 1.8 | L9: -50
A10: Starting FLEX | B10: 1 | C10: RB/WR/TE.
A11: Starting K | B11: 1 | C11: Per team. | E11: Projected points = Pts Slope x Adjusted Rating + Pts Intercept (per position). Tune the curve here.
A12: Starting DST | B12: 1 | C12: Per team.
A13: Bench | B13: 6 | C13: Per team.
A14: K Draft Penalty | B14: 18 | C14: Higher = drafts later.
A15: DST Draft Penalty | B15: 20 | C15: Higher = drafts later.
A16: QB 1QB Penalty | B16: 3 | C16: Set lower in Superflex.
A17: DST Gate Start | B17: 131 | C17: Top DSTs locked to overall 131-140.
A18: K Gate Start | B18: 141 | C18: Top Ks locked to overall 141-150. Keep = DST gate + gate size.
A19: Gate Size | B19: 10 | C19: How many DST/K get gated slots.
A21: Skill players (calc) | B21: =COUNTIF('LIVE SOURCE'!$A$3:$A$232,"QB")+COUNTIF('LIVE SOURCE'!$A$3:$A$232,"RB")+COUNTIF('LIVE SOURCE'!$A$3:$A$232,"WR")+COUNTIF('LIVE SOURCE'!$A$3:$A$232,"TE") -> 186
A22: DST count (calc) | B22: =COUNTIF('LIVE SOURCE'!$A$3:$A$232,"DST") -> 32

Sheet Manual Adjustments
A1: Manual Injury / Role Adjustments (the only place you tweak players)
A2: Pos | B2: Player | C2: Base Rating | D2: Injury Adj | E2: Role Adj | F2: Other Adj | G2: Total Adj | H2: News / Reason | I2: Last Updated | J2: Source
A3: ='LIVE SOURCE'!A3 -> QB | B3: ='LIVE SOURCE'!B3 -> Josh Allen | C3: ='LIVE SOURCE'!D3 -> 97.3099 | G3: =SUM(D3:F3) -> 0 | I3: 2026-08-12
A4: ='LIVE SOURCE'!A4 -> QB | B4: ='LIVE SOURCE'!B4 -> Caleb Williams | C4: ='LIVE SOURCE'!D4 -> 92.1927 | G4: =SUM(D4:F4) -> 0 | I4: 2026-08-12
A5: ='LIVE SOURCE'!A5 -> QB | B5: ='LIVE SOURCE'!B5 -> Drake Maye | C5: ='LIVE SOURCE'!D5 -> 91.043 | G5: =SUM(D5:F5) -> 0 | I5: 2026-08-12
A6: ='LIVE SOURCE'!A6 -> QB | B6: ='LIVE SOURCE'!B6 -> Justin Herbert | C6: ='LIVE SOURCE'!D6 -> 90.1169 | G6: =SUM(D6:F6) -> 0 | I6: 2026-08-12
A7: ='LIVE SOURCE'!A7 -> QB | B7: ='LIVE SOURCE'!B7 -> Lamar Jackson | C7: ='LIVE SOURCE'!D7 -> 88.7112 | G7: =SUM(D7:F7) -> 0 | I7: 2026-08-12
A8: ='LIVE SOURCE'!A8 -> QB | B8: ='LIVE SOURCE'!B8 -> Jalen Hurts | C8: ='LIVE SOURCE'!D8 -> 88.4499 | G8: =SUM(D8:F8) -> 0 | I8: 2026-08-12
A9: ='LIVE SOURCE'!A9 -> QB | B9: ='LIVE SOURCE'!B9 -> Patrick Mahomes II | C9: ='LIVE SOURCE'!D9 -> 87.0063 | G9: =SUM(D9:F9) -> 0 | I9: 2026-08-12
A10: ='LIVE SOURCE'!A10 -> QB | B10: ='LIVE SOURCE'!B10 -> Jayden Daniels | C10: ='LIVE SOURCE'!D10 -> 86.7003 | G10: =SUM(D10:F10) -> 0 | I10: 2026-08-12
A11: ='LIVE SOURCE'!A11 -> QB | B11: ='LIVE SOURCE'!B11 -> Joe Burrow | C11: ='LIVE SOURCE'!D11 -> 85.5913 | G11: =SUM(D11:F11) -> 0 | I11: 2026-08-12
A12: ='LIVE SOURCE'!A12 -> QB | B12: ='LIVE SOURCE'!B12 -> Matthew Stafford | C12: ='LIVE SOURCE'!D12 -> 85.4197 | G12: =SUM(D12:F12) -> 0 | I12: 2026-08-12
A13: ='LIVE SOURCE'!A13 -> QB | B13: ='LIVE SOURCE'!B13 -> Bo Nix | C13: ='LIVE SOURCE'!D13 -> 85.2485 | G13: =SUM(D13:F13) -> 0 | I13: 2026-08-12
A14: ='LIVE SOURCE'!A14 -> QB | B14: ='LIVE SOURCE'!B14 -> Dak Prescott | C14: ='LIVE SOURCE'!D14 -> 85.1156 | G14: =SUM(D14:F14) -> 0 | I14: 2026-08-12
... A78: ='LIVE SOURCE'!A78 -> RB | B78: ='LIVE SOURCE'!B78 -> Tyler Allgeier | C78: ='LIVE SOURCE'!D78 -> 63.0322 | G78: =SUM(D78:F78) -> 0 | I78: 2026-08-12
A79: ='LIVE SOURCE'!A79 -> RB | B79: ='LIVE SOURCE'!B79 -> Zach Charbonnet | C79: ='LIVE SOURCE'!D79 -> 62.5498 | D79: -25 | G79: =SUM(D79:F79) -> -25 | H79: Jan 2026 playoff ACL; opens on PUP, return may be as late as December (ESPN). Not draftable in a 10-team league. | I79: 2026-08-12
A80: ='LIVE SOURCE'!A80 -> RB | B80: ='LIVE SOURCE'!B80 -> Jonathon Brooks | C80: ='LIVE SOURCE'!D80 -> 62.2 | G80: =SUM(D80:F80) -> 0 | I80: 2026-08-12
A81: ='LIVE SOURCE'!A81 -> RB | B81: ='LIVE SOURCE'!B81 -> Emanuel Wilson | C81: ='LIVE SOURCE'!D81 -> 61.9821 | G81: =SUM(D81:F81) -> 0 | I81: 2026-08-12
A82: ='LIVE SOURCE'!A82 -> RB | B82: ='LIVE SOURCE'!B82 -> Isiah Pacheco | C82: ='LIVE SOURCE'!D82 -> 60.0092 | G82: =SUM(D82:F82) -> 0 | I82: 2026-08-12
A83: ='LIVE SOURCE'!A83 -> RB | B83: ='LIVE SOURCE'!B83 -> Alvin Kamara | C83: ='LIVE SOURCE'!D83 -> 59.15 | G83: =SUM(D83:F83) -> 0 | I83: 2026-08-12
A84: ='LIVE SOURCE'!A84 -> RB | B84: ='LIVE SOURCE'!B84 -> Justice Hill | C84: ='LIVE SOURCE'!D84 -> 54.88 | G84: =SUM(D84:F84) -> 0 | I84: 2026-08-12
A85: ='LIVE SOURCE'!A85 -> RB | B85: ='LIVE SOURCE'!B85 -> Tyjae Spears | C85: ='LIVE SOURCE'!D85 -> 63.4 | G85: =SUM(D85:F85) -> 0 | I85: 2026-08-12
A86: ='LIVE SOURCE'!A86 -> RB | B86: ='LIVE SOURCE'!B86 -> Keaton Mitchell | C86: ='LIVE SOURCE'!D86 -> 59 | G86: =SUM(D86:F86) -> 0 | I86: 2026-08-12
A87: ='LIVE SOURCE'!A87 -> WR | B87: ='LIVE SOURCE'!B87 -> Ja'Marr Chase | C87: ='LIVE SOURCE'!D87 -> 96.7323 | G87: =SUM(D87:F87) -> 0 | I87: 2026-08-12
A88: ='LIVE SOURCE'!A88 -> WR | B88: ='LIVE SOURCE'!B88 -> Puka Nacua | C88: ='LIVE SOURCE'!D88 -> 98.4859 | G88: =SUM(D88:F88) -> 0 | I88: 2026-08-12
A89: ='LIVE SOURCE'!A89 -> WR | B89: ='LIVE SOURCE'!B89 -> Jaxon Smith-Njigba | C89: ='LIVE SOURCE'!D89 -> 94.0799 | G89: =SUM(D89:F89) -> 0 | I89: 2026-08-12
A90: ='LIVE SOURCE'!A90 -> WR | B90: ='LIVE SOURCE'!B90 -> Amon-Ra St. Brown | C90: ='LIVE SOURCE'!D90 -> 93.2639 | G90: =SUM(D90:F90) -> 0 | I90: 2026-08-12
A91: ='LIVE SOURCE'!A91 -> WR | B91: ='LIVE SOURCE'!B91 -> A.J. Brown | C91: ='LIVE SOURCE'!D91 -> 83.2357 | G91: =SUM(D91:F91) -> 0 | I91: 2026-08-12
... A126: ='LIVE SOURCE'!A126 -> WR | B126: ='LIVE SOURCE'!B126 -> Brian Thomas Jr. | C126: ='LIVE SOURCE'!D126 -> 66.9675 | G126: =SUM(D126:F126) -> 0 | I126: 2026-08-12
A127: ='LIVE SOURCE'!A127 -> WR | B127: ='LIVE SOURCE'!B127 -> Makai Lemon | C127: ='LIVE SOURCE'!D127 -> 72.2 | D127: -3 | G127: =SUM(D127:F127) -> -3 | H127: Camp hamstring issue / missed practice time; temporary downgrade. | I127: 2026-08-12
A128: ='LIVE SOURCE'!A128 -> WR | B128: ='LIVE SOURCE'!B128 -> Parker Washington | C128: ='LIVE SOURCE'!D128 -> 71.53 | G128: =SUM(D128:F128) -> 0 | I128: 2026-08-12
A129: ='LIVE SOURCE'!A129 -> WR | B129: ='LIVE SOURCE'!B129 -> Chris Godwin Jr. | C129: ='LIVE SOURCE'!D129 -> 70.86 | G129: =SUM(D129:F129) -> 0 | I129: 2026-08-12
A130: ='LIVE SOURCE'!A130 -> WR | B130: ='LIVE SOURCE'!B130 -> Quentin Johnston | C130: ='LIVE SOURCE'!D130 -> 70.19 | G130: =SUM(D130:F130) -> 0 | I130: 2026-08-12
A131: ='LIVE SOURCE'!A131 -> WR | B131: ='LIVE SOURCE'!B131 -> Ricky Pearsall | C131: ='LIVE SOURCE'!D131 -> 69.52 | D131: -60 | G131: =SUM(D131:F131) -> -60 | H131: Season-ending PCL surgery announced 8/1/2026; out for the year (NFL.com). | I131: 2026-08-12
A132: ='LIVE SOURCE'!A132 -> WR | B132: ='LIVE SOURCE'!B132 -> Michael Wilson | C132: ='LIVE SOURCE'!D132 -> 68.85 | G132: =SUM(D132:F132) -> 0 | I132: 2026-08-12
A133: ='LIVE SOURCE'!A133 -> WR | B133: ='LIVE SOURCE'!B133 -> Xavier Worthy | C133: ='LIVE SOURCE'!D133 -> 68.18 | G133: =SUM(D133:F133) -> 0 | I133: 2026-08-12
A134: ='LIVE SOURCE'!A134 -> WR | B134: ='LIVE SOURCE'!B134 -> Matthew Golden | C134: ='LIVE SOURCE'!D134 -> 67.51 | G134: =SUM(D134:F134) -> 0 | I134: 2026-08-12
A135: ='LIVE SOURCE'!A135 -> WR | B135: ='LIVE SOURCE'!B135 -> Josh Downs | C135: ='LIVE SOURCE'!D135 -> 66.84 | G135: =SUM(D135:F135) -> 0 | I135: 2026-08-12
A136: ='LIVE SOURCE'!A136 -> WR | B136: ='LIVE SOURCE'!B136 -> Jayden Reed | C136: ='LIVE SOURCE'!D136 -> 66.17 | G136: =SUM(D136:F136) -> 0 | I136: 2026-08-12
A137: ='LIVE SOURCE'!A137 -> WR | B137: ='LIVE SOURCE'!B137 -> Khalil Shakir | C137: ='LIVE SOURCE'!D137 -> 65.5 | G137: =SUM(D137:F137) -> 0 | I137: 2026-08-12
...

Sheet LIVE SOURCE
A1: LIVE SOURCE: the one canonical table. Every other tab reads from here.
A2: Pos | B2: Player | C2: Team | D2: Base Rating | E2: Market ADP | F2: Confidence | G2: Model Path | H2: 2026 Expectation | I2: Why | J2: Main Risk | K2: Source | L2: Bye
A3: QB | B3: Josh Allen | C3: BUF | D3: 97.3099 | E3: 26.6 | F3: A | G3: RATE-ADJUSTED VETERAN | H3: Elite QB1; weekly top-5 expectation with overall QB1 upside. | I3: He produced 22.0 PPR/FP points per game across 17 games. The workload/efficiency profile gives the model a rate-based reason to keep him here. Market price is favorable around ADP 23 versus model overall rank 10. | J3: Passing-TD efficiency, rushing volume and supporting-cast health are the main swing factors. | K3: https://www.fantasypros.com/nfl/adp/ppr-overall.php | L3: 7
A4: QB | B4: Caleb Williams | C4: CHI | D4: 92.1927 | E4: 107.5 | F4: A | G4: RATE-ADJUSTED VETERAN | H4: Elite QB1; weekly top-5 expectation with overall QB1 upside. | I4: He produced 19.0 PPR/FP points per game across 17 games. The workload/efficiency profile gives the model a rate-based reason to keep him here. | J4: Passing-TD efficiency, rushing volume and supporting-cast health are the main swing factors. | K4: ADP proxy — editable; based on positional draft cost | L4: 10
A5: QB | B5: Drake Maye | C5: NE | D5: 91.043 | E5: 49.8 | F5: A | G5: RATE-ADJUSTED VETERAN | H5: Elite QB1; weekly top-5 expectation with overall QB1 upside. | I5: He produced 21.1 PPR/FP points per game across 17 games. The workload/efficiency profile gives the model a rate-based reason to keep him here. | J5: Passing-TD efficiency, rushing volume and supporting-cast health are the main swing factors. | K5: ADP proxy — editable; based on positional draft cost | L5: 11
A6: QB | B6: Justin Herbert | C6: LAC | D6: 90.1169 | E6: 104.2 | F6: A | G6: RATE-ADJUSTED VETERAN | H6: Strong every-week QB1; frequent top-8 finishes expected. | I6: He produced 18.7 PPR/FP points per game across 16 games. The workload/efficiency profile gives the model a rate-based reason to keep him here. | J6: Passing-TD efficiency, rushing volume and supporting-cast health are the main swing factors. | K6: ADP proxy — editable; based on positional draft cost | L6: 7
A7: QB | B7: Lamar Jackson | C7: BAL | D7: 88.7112 | E7: 52.6 | F7: A | G7: RATE-ADJUSTED VETERAN | H7: Strong every-week QB1; frequent top-8 finishes expected. | I7: He produced 17.1 PPR/FP points per game across 13 games. The workload/efficiency profile gives the model a rate-based reason to keep him here. | J7: Passing-TD efficiency, rushing volume and supporting-cast health are the main swing factors. | K7: ADP proxy — editable; based on positional draft cost | L7: 13
A8: QB | B8: Jalen Hurts | C8: PHI | D8: 88.4499 | E8: 73.7 | F8: A | G8: RATE-ADJUSTED VETERAN | H8: Strong every-week QB1; frequent top-8 finishes expected. | I8: He produced 19.1 PPR/FP points per game across 16 games. The workload/efficiency profile gives the model a rate-based reason to keep him here. | J8: Passing-TD efficiency, rushing volume and supporting-cast health are the main swing factors. | K8: ADP proxy — editable; based on positional draft cost | L8: 10
A9: QB | B9: Patrick Mahomes II | C9: KC | D9: 87.0063 | E9: 97.4 | F9: A | G9: RATE-ADJUSTED VETERAN | H9: Strong every-week QB1; frequent top-8 finishes expected. | I9: He produced 21.1 PPR/FP points per game across 14 games. The workload/efficiency profile gives the model a rate-based reason to keep him here. | J9: Passing-TD efficiency, rushing volume and supporting-cast health are the main swing factors. | K9: ADP proxy — editable; based on positional draft cost | L9: 5
A10: QB | B10: Jayden Daniels | C10: WAS | D10: 86.7003 | E10: 67 | F10: B | G10: RATE-ADJUSTED VETERAN | H10: Strong every-week QB1; frequent top-8 finishes expected. | I10: He produced 16.7 PPR/FP points per game across 7 games. The workload/efficiency profile gives the model a rate-based reason to keep him here. Market price is favorable around ADP 78 versus model overall rank 64. | J10: Availability/sample risk is elevated after only 7 games; talent is not being punished as heavily as durability. | K10: ADP proxy — editable; based on positional draft cost | L10: 7
A11: QB | B11: Joe Burrow | C11: CIN | D11: 85.5913 | E11: 57.3 | F11: B | G11: RATE-ADJUSTED VETERAN | H11: Low-end QB1/high-end QB2 in a 10-team league; startable most weeks. | I11: He produced 17.4 PPR/FP points per game across 8 games. The workload/efficiency profile gives the model a rate-based reason to keep him here. Market price is favorable around ADP 86 versus model overall rank 70. | J11: Availability/sample risk is elevated after only 8 games; talent is not being punished as heavily as durability. | K11: ADP proxy — editable; based on positional draft cost | L11: 6
A12: QB | B12: Matthew Stafford | C12: LAR | D12: 85.4197 | E12: 83.7 | F12: A | G12: RATE-ADJUSTED VETERAN | H12: Low-end QB1/high-end QB2 in a 10-team league; startable most weeks. | I12: He produced 21.1 PPR/FP points per game across 17 games. The workload/efficiency profile gives the model a rate-based reason to keep him here. Market price is favorable around ADP 94 versus model overall rank 77. | J12: Passing-TD efficiency, rushing volume and supporting-cast health are the main swing factors. | K12: ADP proxy — editable; based on positional draft cost | L12: 11
A13: QB | B13: Bo Nix | C13: DEN | D13: 85.2485 | E13: 121.5 | F13: A | G13: RATE-ADJUSTED VETERAN | H13: Low-end QB1/high-end QB2 in a 10-team league; startable most weeks. | I13: He produced 18.6 PPR/FP points per game across 17 games. The workload/efficiency profile gives the model a rate-based reason to keep him here. Market price is favorable around ADP 102 versus model overall rank 79. | J13: Passing-TD efficiency, rushing volume and supporting-cast health are the main swing factors. | K13: ADP proxy — editable; based on positional draft cost | L13: 10
A14: QB | B14: Dak Prescott | C14: DAL | D14: 85.1156 | E14: 65.4 | F14: A | G14: RATE-ADJUSTED VETERAN | H14: Low-end QB1/high-end QB2 in a 10-team league; startable most weeks. | I14: He produced 19.0 PPR/FP points per game across 17 games. The workload/efficiency profile gives the model a rate-based reason to keep him here. Market price is favorable around ADP 110 versus model overall rank 82. | J14: Passing-TD efficiency, rushing volume and supporting-cast health are the main swing factors. | K14: ADP proxy — editable; based on positional draft cost | L14: 14
... A232: DST | B232: Las Vegas Raiders | C232: LV | D232: 58.9 | E232: 284 | F232: B | G232: DST MODEL | H232: Streaming/late-round defense; matchup matters more than preseason rank. | I232: The unit grades well relative to the current DST pool, but the model intentionally keeps defense behind core skill positions. | J232: DST scoring is highly opponent- and turnover-dependent, making season-long rank fragile. | K232: https://www.si.com/fantasy/2026-football-defense-rankings-seasonal-leagues | L232: 13

Sheet FINAL Master
A1: 2026 FINAL Master: every player, live-ranked, K/DST gated to the final rounds.
A2: Overall | B2: Pos | C2: Pos Rank | D2: Player / Defense | E2: Adj Rating | F2: Tier | G2: Proj Points | H2: VORP | I2: Draft Score | J2: Market ADP | K2: Draft Edge | L2: Confidence | M2: Model Path | N2: 2026 Expectation | O2: Main Risk | P2: Src
A3: =1 -> 1 | B3: =INDEX('Draft Engine'!$A$3:$A$232,$P3) -> WR | C3: =INDEX('Draft Engine'!$F$3:$F$232,$P3) -> 1 | D3: =INDEX('Draft Engine'!$B$3:$B$232,$P3) -> Puka Nacua | E3: =INDEX('Draft Engine'!$E$3:$E$232,$P3) -> 98.4859 | F3: =IF($E3>=95,"ELITE",IF($E3>=90,"TIER 1",IF($E3>=85,"TIER 2",IF($E3>=80,"TIER 3",IF($E3>=75,"TIER 4",IF($E3>=70,"TIER 5",IF($E3>=65,"TIER 6","TIER 7"))))))) -> ELITE | G3: =INDEX('Draft Engine'!$G$3:$G$232,$P3) -> 343.6 | H3: =INDEX('Draft Engine'!$J$3:$J$232,$P3) -> 104.3 | I3: =INDEX('Draft Engine'!$N$3:$N$232,$P3) -> 99.167245 | J3: =INDEX('Draft Engine'!$R$3:$R$232,$P3) -> 2.9 | K3: =INDEX('Draft Engine'!$S$3:$S$232,$P3) -> 1.9 | L3: =INDEX('Draft Engine'!$T$3:$T$232,$P3) -> A | M3: =INDEX('Draft Engine'!$X$3:$X$232,$P3) -> HISTORY FALLBACK | N3: =INDEX('LIVE SOURCE'!$H$3:$H$232,$P3) -> Elite WR1 and first-round caliber target with overall WR1 upside. | O3: =INDEX('LIVE SOURCE'!$J$3:$J$232,$P3) -> Target competition, quarterback efficiency and touchdown regression are the main downside paths. | P3: =MATCH($A3,'Draft Engine'!$Q$3:$Q$232,0) -> 86
A4: =2 -> 2 | B4: =INDEX('Draft Engine'!$A$3:$A$232,$P4) -> RB | C4: =INDEX('Draft Engine'!$F$3:$F$232,$P4) -> 1 | D4: =INDEX('Draft Engine'!$B$3:$B$232,$P4) -> Bijan Robinson | E4: =INDEX('Draft Engine'!$E$3:$E$232,$P4) -> 97.3673 | F4: =IF($E4>=95,"ELITE",IF($E4>=90,"TIER 1",IF($E4>=85,"TIER 2",IF($E4>=80,"TIER 3",IF($E4>=75,"TIER 4",IF($E4>=70,"TIER 5",IF($E4>=65,"TIER 6","TIER 7"))))))) -> ELITE | G4: =INDEX('Draft Engine'!$G$3:$G$232,$P4) -> 338.9 | H4: =INDEX('Draft Engine'!$J$3:$J$232,$P4) -> 99.9 | I4: =INDEX('Draft Engine'!$N$3:$N$232,$P4) -> 98.552015 | J4: =INDEX('Draft Engine'!$R$3:$R$232,$P4) -> 1.8 | K4: =INDEX('Draft Engine'!$S$3:$S$232,$P4) -> -0.2 | L4: =INDEX('Draft Engine'!$T$3:$T$232,$P4) -> A | M4: =INDEX('Draft Engine'!$X$3:$X$232,$P4) -> RATE-ADJUSTED VETERAN | N4: =INDEX('LIVE SOURCE'!$H$3:$H$232,$P4) -> Elite RB1 and first-round roster anchor with league-winning ceiling. | O4: =INDEX('LIVE SOURCE'!$J$3:$J$232,$P4) -> Touchdown variance, receiving-role changes and backfield competition are the main downside paths. | P4: =MATCH($A4,'Draft Engine'!$Q$3:$Q$232,0) -> 33
A5: =3 -> 3 | B5: =INDEX('Draft Engine'!$A$3:$A$232,$P5) -> WR | C5: =INDEX('Draft Engine'!$F$3:$F$232,$P5) -> 2 | D5: =INDEX('Draft Engine'!$B$3:$B$232,$P5) -> Ja'Marr Chase | E5: =INDEX('Draft Engine'!$E$3:$E$232,$P5) -> 96.7323 | F5: =IF($E5>=95,"ELITE",IF($E5>=90,"TIER 1",IF($E5>=85,"TIER 2",IF($E5>=80,"TIER 3",IF($E5>=75,"TIER 4",IF($E5>=70,"TIER 5",IF($E5>=65,"TIER 6","TIER 7"))))))) -> ELITE | G5: =INDEX('Draft Engine'!$G$3:$G$232,$P5) -> 336.3 | H5: =INDEX('Draft Engine'!$J$3:$J$232,$P5) -> 97 | I5: =INDEX('Draft Engine'!$N$3:$N$232,$P5) -> 98.202765 | J5: =INDEX('Draft Engine'!$R$3:$R$232,$P5) -> 3.9 | K5: =INDEX('Draft Engine'!$S$3:$S$232,$P5) -> 0.9 | L5: =INDEX('Draft Engine'!$T$3:$T$232,$P5) -> A | M5: =INDEX('Draft Engine'!$X$3:$X$232,$P5) -> HISTORY FALLBACK | N5: =INDEX('LIVE SOURCE'!$H$3:$H$232,$P5) -> Elite WR1 and first-round caliber target with overall WR1 upside. | O5: =INDEX('LIVE SOURCE'!$J$3:$J$232,$P5) -> Target competition, quarterback efficiency and touchdown regression are the main downside paths. | P5: =MATCH($A5,'Draft Engine'!$Q$3:$Q$232,0) -> 85
A6: =4 -> 4 | B6: =INDEX('Draft Engine'!$A$3:$A$232,$P6) -> RB | C6: =INDEX('Draft Engine'!$F$3:$F$232,$P6) -> 2 | D6: =INDEX('Draft Engine'!$B$3:$B$232,$P6) -> Jahmyr Gibbs | E6: =INDEX('Draft Engine'!$E$3:$E$232,$P6) -> 96.3323 | F6: =IF($E6>=95,"ELITE",IF($E6>=90,"TIER 1",IF($E6>=85,"TIER 2",IF($E6>=80,"TIER 3",IF($E6>=75,"TIER 4",IF($E6>=70,"TIER 5",IF($E6>=65,"TIER 6","TIER 7"))))))) -> ELITE | G6: =INDEX('Draft Engine'!$G$3:$G$232,$P6) -> 334.6 | H6: =INDEX('Draft Engine'!$J$3:$J$232,$P6) -> 95.6 | I6: =INDEX('Draft Engine'!$N$3:$N$232,$P6) -> 97.982765 | J6: =INDEX('Draft Engine'!$R$3:$R$232,$P6) -> 1.8 | K6: =INDEX('Draft Engine'!$S$3:$S$232,$P6) -> -2.2 | L6: =INDEX('Draft Engine'!$T$3:$T$232,$P6) -> A | M6: =INDEX('Draft Engine'!$X$3:$X$232,$P6) -> RATE-ADJUSTED VETERAN | N6: =INDEX('LIVE SOURCE'!$H$3:$H$232,$P6) -> Elite RB1 and first-round roster anchor with league-winning ceiling. | O6: =INDEX('LIVE SOURCE'!$J$3:$J$232,$P6) -> Touchdown variance, receiving-role changes and backfield competition are the main downside paths. | P6: =MATCH($A6,'Draft Engine'!$Q$3:$Q$232,0) -> 34
A7: =5 -> 5 | B7: =INDEX('Draft Engine'!$A$3:$A$232,$P7) -> RB | C7: =INDEX('Draft Engine'!$F$3:$F$232,$P7) -> 3 | D7: =INDEX('Draft Engine'!$B$3:$B$232,$P7) -> Christian McCaffrey | E7: =INDEX('Draft Engine'!$E$3:$E$232,$P7) -> 94.2447 | F7: =IF($E7>=95,"ELITE",IF($E7>=90,"TIER 1",IF($E7>=85,"TIER 2",IF($E7>=80,"TIER 3",IF($E7>=75,"TIER 4",IF($E7>=70,"TIER 5",IF($E7>=65,"TIER 6","TIER 7"))))))) -> TIER 1 | G7: =INDEX('Draft Engine'!$G$3:$G$232,$P7) -> 325.8 | H7: =INDEX('Draft Engine'!$J$3:$J$232,$P7) -> 86.8 | I7: =INDEX('Draft Engine'!$N$3:$N$232,$P7) -> 96.834585 | J7: =INDEX('Draft Engine'!$R$3:$R$232,$P7) -> 5.8 | K7: =INDEX('Draft Engine'!$S$3:$S$232,$P7) -> 0.8 | L7: =INDEX('Draft Engine'!$T$3:$T$232,$P7) -> A | M7: =INDEX('Draft Engine'!$X$3:$X$232,$P7) -> RATE-ADJUSTED VETERAN | N7: =INDEX('LIVE SOURCE'!$H$3:$H$232,$P7) -> Elite RB1 and first-round roster anchor with league-winning ceiling. | O7: =INDEX('LIVE SOURCE'!$J$3:$J$232,$P7) -> Touchdown variance, receiving-role changes and backfield competition are the main downside paths. | P7: =MATCH($A7,'Draft Engine'!$Q$3:$Q$232,0) -> 35
A8: =6 -> 6 | B8: =INDEX('Draft Engine'!$A$3:$A$232,$P8) -> WR | C8: =INDEX('Draft Engine'!$F$3:$F$232,$P8) -> 3 | D8: =INDEX('Draft Engine'!$B$3:$B$232,$P8) -> Jaxon Smith-Njigba | E8: =INDEX('Draft Engine'!$E$3:$E$232,$P8) -> 94.0799 | F8: =IF($E8>=95,"ELITE",IF($E8>=90,"TIER 1",IF($E8>=85,"TIER 2",IF($E8>=80,"TIER 3",IF($E8>=75,"TIER 4",IF($E8>=70,"TIER 5",IF($E8>=65,"TIER 6","TIER 7"))))))) -> TIER 1 | G8: =INDEX('Draft Engine'!$G$3:$G$232,$P8) -> 325.1 | H8: =INDEX('Draft Engine'!$J$3:$J$232,$P8) -> 85.8 | I8: =INDEX('Draft Engine'!$N$3:$N$232,$P8) -> 96.743945 | J8: =INDEX('Draft Engine'!$R$3:$R$232,$P8) -> 5.7 | K8: =INDEX('Draft Engine'!$S$3:$S$232,$P8) -> -0.3 | L8: =INDEX('Draft Engine'!$T$3:$T$232,$P8) -> A | M8: =INDEX('Draft Engine'!$X$3:$X$232,$P8) -> HISTORY FALLBACK | N8: =INDEX('LIVE SOURCE'!$H$3:$H$232,$P8) -> Elite WR1 and first-round caliber target with overall WR1 upside. | O8: =INDEX('LIVE SOURCE'!$J$3:$J$232,$P8) -> Target competition, quarterback efficiency and touchdown regression are the main downside paths. | P8: =MATCH($A8,'Draft Engine'!$Q$3:$Q$232,0) -> 87
A9: =7 -> 7 | B9: =INDEX('Draft Engine'!$A$3:$A$232,$P9) -> WR | C9: =INDEX('Draft Engine'!$F$3:$F$232,$P9) -> 4 | D9: =INDEX('Draft Engine'!$B$3:$B$232,$P9) -> Amon-Ra St. Brown | E9: =INDEX('Draft Engine'!$E$3:$E$232,$P9) -> 93.2639 | F9: =IF($E9>=95,"ELITE",IF($E9>=90,"TIER 1",IF($E9>=85,"TIER 2",IF($E9>=80,"TIER 3",IF($E9>=75,"TIER 4",IF($E9>=70,"TIER 5",IF($E9>=65,"TIER 6","TIER 7"))))))) -> TIER 1 | G9: =INDEX('Draft Engine'!$G$3:$G$232,$P9) -> 321.7 | H9: =INDEX('Draft Engine'!$J$3:$J$232,$P9) -> 82.4 | I9: =INDEX('Draft Engine'!$N$3:$N$232,$P9) -> 96.127145 | J9: =INDEX('Draft Engine'!$R$3:$R$232,$P9) -> 7 | K9: =INDEX('Draft Engine'!$S$3:$S$232,$P9) -> 0 | L9: =INDEX('Draft Engine'!$T$3:$T$232,$P9) -> A | M9: =INDEX('Draft Engine'!$X$3:$X$232,$P9) -> HISTORY FALLBACK | N9: =INDEX('LIVE SOURCE'!$H$3:$H$232,$P9) -> Elite WR1 and first-round caliber target with overall WR1 upside. | O9: =INDEX('LIVE SOURCE'!$J$3:$J$232,$P9) -> Target competition, quarterback efficiency and touchdown regression are the main downside paths. | P9: =MATCH($A9,'Draft Engine'!$Q$3:$Q$232,0) -> 88
A10: =8 -> 8 | B10: =INDEX('Draft Engine'!$A$3:$A$232,$P10) -> RB | C10: =INDEX('Draft Engine'!$F$3:$F$232,$P10) -> 4 | D10: =INDEX('Draft Engine'!$B$3:$B$232,$P10) -> Jonathan Taylor | E10: =INDEX('Draft Engine'!$E$3:$E$232,$P10) -> 92.147 | F10: =IF($E10>=95,"ELITE",IF($E10>=90,"TIER 1",IF($E10>=85,"TIER 2",IF($E10>=80,"TIER 3",IF($E10>=75,"TIER 4",IF($E10>=70,"TIER 5",IF($E10>=65,"TIER 6","TIER 7"))))))) -> TIER 1 | G10: =INDEX('Draft Engine'!$G$3:$G$232,$P10) -> 317 | H10: =INDEX('Draft Engine'!$J$3:$J$232,$P10) -> 78 | I10: =INDEX('Draft Engine'!$N$3:$N$232,$P10) -> 94.72085 | J10: =INDEX('Draft Engine'!$R$3:$R$232,$P10) -> 7.4 | K10: =INDEX('Draft Engine'!$S$3:$S$232,$P10) -> -0.6 | L10: =INDEX('Draft Engine'!$T$3:$T$232,$P10) -> A | M10: =INDEX('Draft Engine'!$X$3:$X$232,$P10) -> RATE-ADJUSTED VETERAN | N10: =INDEX('LIVE SOURCE'!$H$3:$H$232,$P10) -> Elite RB1 and first-round roster anchor with league-winning ceiling. | O10: =INDEX('LIVE SOURCE'!$J$3:$J$232,$P10) -> Touchdown variance, receiving-role changes and backfield competition are the main downside paths. | P10: =MATCH($A10,'Draft Engine'!$Q$3:$Q$232,0) -> 36
A11: =9 -> 9 | B11: =INDEX('Draft Engine'!$A$3:$A$232,$P11) -> WR | C11: =INDEX('Draft Engine'!$F$3:$F$232,$P11) -> 5 | D11: =INDEX('Draft Engine'!$B$3:$B$232,$P11) -> Nico Collins | E11: =INDEX('Draft Engine'!$E$3:$E$232,$P11) -> 91.4925 | F11: =IF($E11>=95,"ELITE",IF($E11>=90,"TIER 1",IF($E11>=85,"TIER 2",IF($E11>=80,"TIER 3",IF($E11>=75,"TIER 4",IF($E11>=70,"TIER 5",IF($E11>=65,"TIER 6","TIER 7"))))))) -> TIER 1 | G11: =INDEX('Draft Engine'!$G$3:$G$232,$P11) -> 314.3 | H11: =INDEX('Draft Engine'!$J$3:$J$232,$P11) -> 75 | I11: =INDEX('Draft Engine'!$N$3:$N$232,$P11) -> 93.820875 | J11: =INDEX('Draft Engine'!$R$3:$R$232,$P11) -> 23.8 | K11: =INDEX('Draft Engine'!$S$3:$S$232,$P11) -> 14.8 | L11: =INDEX('Draft Engine'!$T$3:$T$232,$P11) -> B | M11: =INDEX('Draft Engine'!$X$3:$X$232,$P11) -> HISTORY FALLBACK | N11: =INDEX('LIVE SOURCE'!$H$3:$H$232,$P11) -> Elite WR1 and first-round caliber target with overall WR1 upside. | O11: =INDEX('LIVE SOURCE'!$J$3:$J$232,$P11) -> Target competition, quarterback efficiency and touchdown regression are the main downside paths. | P11: =MATCH($A11,'Draft Engine'!$Q$3:$Q$232,0) -> 94
A12: =10 -> 10 | B12: =INDEX('Draft Engine'!$A$3:$A$232,$P12) -> TE | C12: =INDEX('Draft Engine'!$F$3:$F$232,$P12) -> 1 | D12: =INDEX('Draft Engine'!$B$3:$B$232,$P12) -> Trey McBride | E12: =INDEX('Draft Engine'!$E$3:$E$232,$P12) -> 97.7371 | F12: =IF($E12>=95,"ELITE",IF($E12>=90,"TIER 1",IF($E12>=85,"TIER 2",IF($E12>=80,"TIER 3",IF($E12>=75,"TIER 4",IF($E12>=70,"TIER 5",IF($E12>=65,"TIER 6","TIER 7"))))))) -> ELITE | G12: =INDEX('Draft Engine'!$G$3:$G$232,$P12) -> 242.1 | H12: =INDEX('Draft Engine'!$J$3:$J$232,$P12) -> 62.4 | I12: =INDEX('Draft Engine'!$N$3:$N$232,$P12) -> 93.487405 | J12: =INDEX('Draft Engine'!$R$3:$R$232,$P12) -> 35.7 | K12: =INDEX('Draft Engine'!$S$3:$S$232,$P12) -> 25.7 | L12: =INDEX('Draft Engine'!$T$3:$T$232,$P12) -> A | M12: =INDEX('Draft Engine'!$X$3:$X$232,$P12) -> RATE-ADJUSTED VETERAN | N12: =INDEX('LIVE SOURCE'!$H$3:$H$232,$P12) -> Elite difference-making TE; positional advantage is the expectation. | O12: =INDEX('LIVE SOURCE'!$J$3:$J$232,$P12) -> Route share, target volume and touchdown volatility are the main swing factors. | P12: =MATCH($A12,'Draft Engine'!$Q$3:$Q$232,0) -> 159
A13: =11 -> 11 | B13: =INDEX('Draft Engine'!$A$3:$A$232,$P13) -> RB | C13: =INDEX('Draft Engine'!$F$3:$F$232,$P13) -> 5 | D13: =INDEX('Draft Engine'!$B$3:$B$232,$P13) -> Jeremiyah Love | E13: =INDEX('Draft Engine'!$E$3:$E$232,$P13) -> 90.8659 | F13: =IF($E13>=95,"ELITE",IF($E13>=90,"TIER 1",IF($E13>=85,"TIER 2",IF($E13>=80,"TIER 3",IF($E13>=75,"TIER 4",IF($E13>=70,"TIER 5",IF($E13>=65,"TIER 6","TIER 7"))))))) -> TIER 1 | G13: =INDEX('Draft Engine'!$G$3:$G$232,$P13) -> 311.6 | H13: =INDEX('Draft Engine'!$J$3:$J$232,$P13) -> 72.6 | I13: =INDEX('Draft Engine'!$N$3:$N$232,$P13) -> 93.044245 | J13: =INDEX('Draft Engine'!$R$3:$R$232,$P13) -> 26.2 | K13: =INDEX('Draft Engine'!$S$3:$S$232,$P13) -> 15.2 | L13: =INDEX('Draft Engine'!$T$3:$T$232,$P13) -> B | M13: =INDEX('Draft Engine'!$X$3:$X$232,$P13) -> ROOKIE ENGINE | N13: =INDEX('LIVE SOURCE'!$H$3:$H$232,$P13) -> Elite RB1 and first-round roster anchor with league-winning ceiling. | O13: =INDEX('LIVE SOURCE'!$J$3:$J$232,$P13) -> NFL translation and exact weekly role are the main variables; preseason first-team usage can move this rating quickly. | P13: =MATCH($A13,'Draft Engine'!$Q$3:$Q$232,0) -> 37
A14: =12 -> 12 | B14: =INDEX('Draft Engine'!$A$3:$A$232,$P14) -> QB | C14: =INDEX('Draft Engine'!$F$3:$F$232,$P14) -> 1 | D14: =INDEX('Draft Engine'!$B$3:$B$232,$P14) -> Josh Allen | E14: =INDEX('Draft Engine'!$E$3:$E$232,$P14) -> 97.3099 | F14: =IF($E14>=95,"ELITE",IF($E14>=90,"TIER 1",IF($E14>=85,"TIER 2",IF($E14>=80,"TIER 3",IF($E14>=75,"TIER 4",IF($E14>=70,"TIER 5",IF($E14>=65,"TIER 6","TIER 7"))))))) -> ELITE | G14: =INDEX('Draft Engine'!$G$3:$G$232,$P14) -> 407.9 | H14: =INDEX('Draft Engine'!$J$3:$J$232,$P14) -> 56.8 | I14: =INDEX('Draft Engine'!$N$3:$N$232,$P14) -> 90.744445 | J14: =INDEX('Draft Engine'!$R$3:$R$232,$P14) -> 26.6 | K14: =INDEX('Draft Engine'!$S$3:$S$232,$P14) -> 14.6 | L14: =INDEX('Draft Engine'!$T$3:$T$232,$P14) -> A | M14: =INDEX('Draft Engine'!$X$3:$X$232,$P14) -> RATE-ADJUSTED VETERAN | N14: =INDEX('LIVE SOURCE'!$H$3:$H$232,$P14) -> Elite QB1; weekly top-5 expectation with overall QB1 upside. | O14: =INDEX('LIVE SOURCE'!$J$3:$J$232,$P14) -> Passing-TD efficiency, rushing volume and supporting-cast health are the main swing factors. | P14: =MATCH($A14,'Draft Engine'!$Q$3:$Q$232,0) -> 1
A15: =13 -> 13 | B15: =INDEX('Draft Engine'!$A$3:$A$232,$P15) -> WR | C15: =INDEX('Draft Engine'!$F$3:$F$232,$P15) -> 6 | D15: =INDEX('Draft Engine'!$B$3:$B$232,$P15) -> Chris Olave | E15: =INDEX('Draft Engine'!$E$3:$E$232,$P15) -> 88.9075 | F15: =IF($E15>=95,"ELITE",IF($E15>=90,"TIER 1",IF($E15>=85,"TIER 2",IF($E15>=80,"TIER 3",IF($E15>=75,"TIER 4",IF($E15>=70,"TIER 5",IF($E15>=65,"TIER 6","TIER 7"))))))) -> TIER 2 | G15: =INDEX('Draft Engine'!$G$3:$G$232,$P15) -> 303.4 | H15: =INDEX('Draft Engine'!$J$3:$J$232,$P15) -> 64.1 | I15: =INDEX('Draft Engine'!$N$3:$N$232,$P15) -> 90.270458 | J15: =INDEX('Draft Engine'!$R$3:$R$232,$P15) -> 20.4 | K15: =INDEX('Draft Engine'!$S$3:$S$232,$P15) -> 7.4 | L15: =INDEX('Draft Engine'!$T$3:$T$232,$P15) -> B | M15: =INDEX('Draft Engine'!$X$3:$X$232,$P15) -> HISTORY FALLBACK | N15: =INDEX('LIVE SOURCE'!$H$3:$H$232,$P15) -> Strong WR1; bankable weekly starter with spike-week ceiling. | O15: =INDEX('LIVE SOURCE'!$J$3:$J$232,$P15) -> Target competition, quarterback efficiency and touchdown regression are the main downside paths. | P15: =MATCH($A15,'Draft Engine'!$Q$3:$Q$232,0) -> 96
A16: =14 -> 14 | B16: =INDEX('Draft Engine'!$A$3:$A$232,$P16) -> RB | C16: =INDEX('Draft Engine'!$F$3:$F$232,$P16) -> 6 | D16: =INDEX('Draft Engine'!$B$3:$B$232,$P16) -> Omarion Hampton | E16: =INDEX('Draft Engine'!$E$3:$E$232,$P16) -> 88.6421 | F16: =IF($E16>=95,"ELITE",IF($E16>=90,"TIER 1",IF($E16>=85,"TIER 2",IF($E16>=80,"TIER 3",IF($E16>=75,"TIER 4",IF($E16>=70,"TIER 5",IF($E16>=65,"TIER 6","TIER 7"))))))) -> TIER 2 | G16: =INDEX('Draft Engine'!$G$3:$G$232,$P16) -> 302.3 | H16: =INDEX('Draft Engine'!$J$3:$J$232,$P16) -> 63.3 | I16: =INDEX('Draft Engine'!$N$3:$N$232,$P16) -> 90.147155 | J16: =INDEX('Draft Engine'!$R$3:$R$232,$P16) -> 19.6 | K16: =INDEX('Draft Engine'!$S$3:$S$232,$P16) -> 5.6 | L16: =INDEX('Draft Engine'!$T$3:$T$232,$P16) -> B | M16: =INDEX('Draft Engine'!$X$3:$X$232,$P16) -> RATE-ADJUSTED VETERAN | N16: =INDEX('LIVE SOURCE'!$H$3:$H$232,$P16) -> Strong RB1; weekly top-12 expectation with multi-touchdown ceiling. | O16: =INDEX('LIVE SOURCE'!$J$3:$J$232,$P16) -> Availability/sample risk is elevated after only 9 games; talent is not being punished as heavily as durability. | P16: =MATCH($A16,'Draft Engine'!$Q$3:$Q$232,0) -> 38
A17: =15 -> 15 | B17: =INDEX('Draft Engine'!$A$3:$A$232,$P17) -> TE | C17: =INDEX('Draft Engine'!$F$3:$F$232,$P17) -> 2 | D17: =INDEX('Draft Engine'!$B$3:$B$232,$P17) -> Brock Bowers | E17: =INDEX('Draft Engine'!$E$3:$E$232,$P17) -> 94.8846 | F17: =IF($E17>=95,"ELITE",IF($E17>=90,"TIER 1",IF($E17>=85,"TIER 2",IF($E17>=80,"TIER 3",IF($E17>=75,"TIER 4",IF($E17>=70,"TIER 5",IF($E17>=65,"TIER 6","TIER 7"))))))) -> TIER 1 | G17: =INDEX('Draft Engine'!$G$3:$G$232,$P17) -> 232.1 | H17: =INDEX('Draft Engine'!$J$3:$J$232,$P17) -> 52.4 | I17: =INDEX('Draft Engine'!$N$3:$N$232,$P17) -> 89.426222 | J17: =INDEX('Draft Engine'!$R$3:$R$232,$P17) -> 41.1 | K17: =INDEX('Draft Engine'!$S$3:$S$232,$P17) -> 26.1 | L17: =INDEX('Draft Engine'!$T$3:$T$232,$P17) -> A | M17: =INDEX('Draft Engine'!$X$3:$X$232,$P17) -> RATE-ADJUSTED VETERAN | N17: =INDEX('LIVE SOURCE'!$H$3:$H$232,$P17) -> Elite difference-making TE; positional advantage is the expectation. | O17: =INDEX('LIVE SOURCE'!$J$3:$J$232,$P17) -> Route share, target volume and touchdown volatility are the main swing factors. | P17: =MATCH($A17,'Draft Engine'!$Q$3:$Q$232,0) -> 160
A18: =16 -> 16 | B18: =INDEX('Draft Engine'!$A$3:$A$232,$P18) -> RB | C18: =INDEX('Draft Engine'!$F$3:$F$232,$P18) -> 7 | D18: =INDEX('Draft Engine'!$B$3:$B$232,$P18) -> De'Von Achane | E18: =INDEX('Draft Engine'!$E$3:$E$232,$P18) -> 87.944 | F18: =IF($E18>=95,"ELITE",IF($E18>=90,"TIER 1",IF($E18>=85,"TIER 2",IF($E18>=80,"TIER 3",IF($E18>=75,"TIER 4",IF($E18>=70,"TIER 5",IF($E18>=65,"TIER 6","TIER 7"))))))) -> TIER 2 | G18: =INDEX('Draft Engine'!$G$3:$G$232,$P18) -> 299.4 | H18: =INDEX('Draft Engine'!$J$3:$J$232,$P18) -> 60.4 | I18: =INDEX('Draft Engine'!$N$3:$N$232,$P18) -> 89.2412 | J18: =INDEX('Draft Engine'!$R$3:$R$232,$P18) -> 10.1 | K18: =INDEX('Draft Engine'!$S$3:$S$232,$P18) -> -5.9 | L18: =INDEX('Draft Engine'!$T$3:$T$232,$P18) -> A | M18: =INDEX('Draft Engine'!$X$3:$X$232,$P18) -> RATE-ADJUSTED VETERAN | N18: =INDEX('LIVE SOURCE'!$H$3:$H$232,$P18) -> Strong RB1; weekly top-12 expectation with multi-touchdown ceiling. | O18: =INDEX('LIVE SOURCE'!$J$3:$J$232,$P18) -> Touchdown variance, receiving-role changes and backfield competition are the main downside paths. | P18: =MATCH($A18,'Draft Engine'!$Q$3:$Q$232,0) -> 39
A19: =17 -> 17 | B19: =INDEX('Draft Engine'!$A$3:$A$232,$P19) -> RB | C19: =INDEX('Draft Engine'!$F$3:$F$232,$P19) -> 8 | D19: =INDEX('Draft Engine'!$B$3:$B$232,$P19) -> Kenneth Walker III | E19: =INDEX('Draft Engine'!$E$3:$E$232,$P19) -> 87.2926 | F19: =IF($E19>=95,"ELITE",IF($E19>=90,"TIER 1",IF($E19>=85,"TIER 2",IF($E19>=80,"TIER 3",IF($E19>=75,"TIER 4",IF($E19>=70,"TIER 5",IF($E19>=65,"TIER 6","TIER 7"))))))) -> TIER 2 | G19: =INDEX('Draft Engine'!$G$3:$G$232,$P19) -> 296.6 | H19: =INDEX('Draft Engine'!$J$3:$J$232,$P19) -> 57.6 | I19: =INDEX('Draft Engine'!$N$3:$N$232,$P19) -> 88.113305 | J19: =INDEX('Draft Engine'!$R$3:$R$232,$P19) -> 26.2 | K19: =INDEX('Draft Engine'!$S$3:$S$232,$P19) -> 9.2 | L19: =INDEX('Draft Engine'!$T$3:$T$232,$P19) -> A | M19: =INDEX('Draft Engine'!$X$3:$X$232,$P19) -> RATE-ADJUSTED VETERAN | N19: =INDEX('LIVE SOURCE'!$H$3:$H$232,$P19) -> Strong RB1; weekly top-12 expectation with multi-touchdown ceiling. | O19: =INDEX('LIVE SOURCE'!$J$3:$J$232,$P19) -> Touchdown variance, receiving-role changes and backfield competition are the main downside paths. | P19: =MATCH($A19,'Draft Engine'!$Q$3:$Q$232,0) -> 40
A20: =18 -> 18 | B20: =INDEX('Draft Engine'!$A$3:$A$232,$P20) -> WR | C20: =INDEX('Draft Engine'!$F$3:$F$232,$P20) -> 7 | D20: =INDEX('Draft Engine'!$B$3:$B$232,$P20) -> Drake London | E20: =INDEX('Draft Engine'!$E$3:$E$232,$P20) -> 87.5106 | F20: =IF($E20>=95,"ELITE",IF($E20>=90,"TIER 1",IF($E20>=85,"TIER 2",IF($E20>=80,"TIER 3",IF($E20>=75,"TIER 4",IF($E20>=70,"TIER 5",IF($E20>=65,"TIER 6","TIER 7"))))))) -> TIER 2 | G20: =INDEX('Draft Engine'!$G$3:$G$232,$P20) -> 297.5 | H20: =INDEX('Draft Engine'!$J$3:$J$232,$P20) -> 58.2 | I20: =INDEX('Draft Engine'!$N$3:$N$232,$P20) -> 88.10683 | J20: =INDEX('Draft Engine'!$R$3:$R$232,$P20) -> 10.2 | K20: =INDEX('Draft Engine'!$S$3:$S$232,$P20) -> -7.8 | L20: =INDEX('Draft Engine'!$T$3:$T$232,$P20) -> A | M20: =INDEX('Draft Engine'!$X$3:$X$232,$P20) -> HISTORY FALLBACK | N20: =INDEX('LIVE SOURCE'!$H$3:$H$232,$P20) -> Strong WR1; bankable weekly starter with spike-week ceiling. | O20: =INDEX('LIVE SOURCE'!$J$3:$J$232,$P20) -> Target competition, quarterback efficiency and touchdown regression are the main downside paths. | P20: =MATCH($A20,'Draft Engine'!$Q$3:$Q$232,0) -> 93
A21: =19 -> 19 | B21: =INDEX('Draft Engine'!$A$3:$A$232,$P21) -> WR | C21: =INDEX('Draft Engine'!$F$3:$F$232,$P21) -> 8 | D21: =INDEX('Draft Engine'!$B$3:$B$232,$P21) -> DeVonta Smith | E21: =INDEX('Draft Engine'!$E$3:$E$232,$P21) -> 87.4875 | F21: =IF($E21>=95,"ELITE",IF($E21>=90,"TIER 1",IF($E21>=85,"TIER 2",IF($E21>=80,"TIER 3",IF($E21>=75,"TIER 4",IF($E21>=70,"TIER 5",IF($E21>=65,"TIER 6","TIER 7"))))))) -> TIER 2 | G21: =INDEX('Draft Engine'!$G$3:$G$232,$P21) -> 297.4 | H21: =INDEX('Draft Engine'!$J$3:$J$232,$P21) -> 58.1 | I21: =INDEX('Draft Engine'!$N$3:$N$232,$P21) -> 87.742792 | J21: =INDEX('Draft Engine'!$R$3:$R$232,$P21) -> 29.5 | K21: =INDEX('Draft Engine'!$S$3:$S$232,$P21) -> 10.5 | L21: =INDEX('Draft Engine'!$T$3:$T$232,$P21) -> B | M21: =INDEX('Draft Engine'!$X$3:$X$232,$P21) -> HISTORY FALLBACK | N21: =INDEX('LIVE SOURCE'!$H$3:$H$232,$P21) -> Strong WR1; bankable weekly starter with spike-week ceiling. | O21: =INDEX('LIVE SOURCE'!$J$3:$J$232,$P21) -> Target competition, quarterback efficiency and touchdown regression are the main downside paths. | P21: =MATCH($A21,'Draft Engine'!$Q$3:$Q$232,0) -> 100
A22: =20 -> 20 | B22: =INDEX('Draft Engine'!$A$3:$A$232,$P22) -> RB | C22: =INDEX('Draft Engine'!$F$3:$F$232,$P22) -> 9 | D22: =INDEX('Draft Engine'!$B$3:$B$232,$P22) -> James Cook III | E22: =INDEX('Draft Engine'!$E$3:$E$232,$P22) -> 87.058 | F22: =IF($E22>=95,"ELITE",IF($E22>=90,"TIER 1",IF($E22>=85,"TIER 2",IF($E22>=80,"TIER 3",IF($E22>=75,"TIER 4",IF($E22>=70,"TIER 5",IF($E22>=65,"TIER 6","TIER 7"))))))) -> TIER 2 | G22: =INDEX('Draft Engine'!$G$3:$G$232,$P22) -> 295.6 | H22: =INDEX('Draft Engine'!$J$3:$J$232,$P22) -> 56.6 | I22: =INDEX('Draft Engine'!$N$3:$N$232,$P22) -> 87.4449 | J22: =INDEX('Draft Engine'!$R$3:$R$232,$P22) -> 14.9 | K22: =INDEX('Draft Engine'!$S$3:$S$232,$P22) -> -5.1 | L22: =INDEX('Draft Engine'!$T$3:$T$232,$P22) -> A | M22: =INDEX('Draft Engine'!$X$3:$X$232,$P22) -> RATE-ADJUSTED VETERAN | N22: =INDEX('LIVE SOURCE'!$H$3:$H$232,$P22) -> Strong RB1; weekly top-12 expectation with multi-touchdown ceiling. | O22: =INDEX('LIVE SOURCE'!$J$3:$J$232,$P22) -> Touchdown variance, receiving-role changes and backfield competition are the main downside paths. | P22: =MATCH($A22,'Draft Engine'!$Q$3:$Q$232,0) -> 41
A23: =21 -> 21 | B23: =INDEX('Draft Engine'!$A$3:$A$232,$P23) -> WR | C23: =INDEX('Draft Engine'!$F$3:$F$232,$P23) -> 9 | D23: =INDEX('Draft Engine'!$B$3:$B$232,$P23) -> Zay Flowers | E23: =INDEX('Draft Engine'!$E$3:$E$232,$P23) -> 86.57 | F23: =IF($E23>=95,"ELITE",IF($E23>=90,"TIER 1",IF($E23>=85,"TIER 2",IF($E23>=80,"TIER 3",IF($E23>=75,"TIER 4",IF($E23>=70,"TIER 5",IF($E23>=65,"TIER 6","TIER 7"))))))) -> TIER 2 | G23: =INDEX('Draft Engine'!$G$3:$G$232,$P23) -> 293.6 | H23: =INDEX('Draft Engine'!$J$3:$J$232,$P23) -> 54.3 | I23: =INDEX('Draft Engine'!$N$3:$N$232,$P23) -> 86.220833 | J23: =INDEX('Draft Engine'!$R$3:$R$232,$P23) -> 26.4 | K23: =INDEX('Draft Engine'!$S$3:$S$232,$P23) -> 5.4 | L23: =INDEX('Draft Engine'!$T$3:$T$232,$P23) -> B | M23: =INDEX('Draft Engine'!$X$3:$X$232,$P23) -> HISTORY FALLBACK | N23: =INDEX('LIVE SOURCE'!$H$3:$H$232,$P23) -> Strong WR1; bankable weekly starter with spike-week ceiling. | O23: =INDEX('LIVE SOURCE'!$J$3:$J$232,$P23) -> Target competition, quarterback efficiency and touchdown regression are the main downside paths. | P23: =MATCH($A23,'Draft Engine'!$Q$3:$Q$232,0) -> 101
A24: =22 -> 22 | B24: =INDEX('Draft Engine'!$A$3:$A$232,$P24) -> RB | C24: =INDEX('Draft Engine'!$F$3:$F$232,$P24) -> 10 | D24: =INDEX('Draft Engine'!$B$3:$B$232,$P24) -> Kyren Williams | E24: =INDEX('Draft Engine'!$E$3:$E$232,$P24) -> 85.9486 | F24: =IF($E24>=95,"ELITE",IF($E24>=90,"TIER 1",IF($E24>=85,"TIER 2",IF($E24>=80,"TIER 3",IF($E24>=75,"TIER 4",IF($E24>=70,"TIER 5",IF($E24>=65,"TIER 6","TIER 7"))))))) -> TIER 2 | G24: =INDEX('Draft Engine'!$G$3:$G$232,$P24) -> 291 | H24: =INDEX('Draft Engine'!$J$3:$J$232,$P24) -> 52 | I24: =INDEX('Draft Engine'!$N$3:$N$232,$P24) -> 85.647355 | J24: =INDEX('Draft Engine'!$R$3:$R$232,$P24) -> 33.1 | K24: =INDEX('Draft Engine'!$S$3:$S$232,$P24) -> 11.1 | L24: =INDEX('Draft Engine'!$T$3:$T$232,$P24) -> A | M24: =INDEX('Draft Engine'!$X$3:$X$232,$P24) -> RATE-ADJUSTED VETERAN | N24: =INDEX('LIVE SOURCE'!$H$3:$H$232,$P24) -> Strong RB1; weekly top-12 expectation with multi-touchdown ceiling. | O24: =INDEX('LIVE SOURCE'!$J$3:$J$232,$P24) -> Touchdown variance, receiving-role changes and backfield competition are the main downside paths. | P24: =MATCH($A24,'Draft Engine'!$Q$3:$Q$232,0) -> 42
A25: =23 -> 23 | B25: =INDEX('Draft Engine'!$A$3:$A$232,$P25) -> WR | C25: =INDEX('Draft Engine'!$F$3:$F$232,$P25) -> 10 | D25: =INDEX('Draft Engine'!$B$3:$B$232,$P25) -> Garrett Wilson | E25: =INDEX('Draft Engine'!$E$3:$E$232,$P25) -> 86.155 | F25: =IF($E25>=95,"ELITE",IF($E25>=90,"TIER 1",IF($E25>=85,"TIER 2",IF($E25>=80,"TIER 3",IF($E25>=75,"TIER 4",IF($E25>=70,"TIER 5",IF($E25>=65,"TIER 6","TIER 7"))))))) -> TIER 2 | G25: =INDEX('Draft Engine'!$G$3:$G$232,$P25) -> 291.9 | H25: =INDEX('Draft Engine'!$J$3:$J$232,$P25) -> 52.6 | I25: =INDEX('Draft Engine'!$N$3:$N$232,$P25) -> 85.35325 | J25: =INDEX('Draft Engine'!$R$3:$R$232,$P25) -> 29 | K25: =INDEX('Draft Engine'!$S$3:$S$232,$P25) -> 6 | L25: =INDEX('Draft Engine'!$T$3:$T$232,$P25) -> B | M25: =INDEX('Draft Engine'!$X$3:$X$232,$P25) -> HISTORY FALLBACK | N25: =INDEX('LIVE SOURCE'!$H$3:$H$232,$P25) -> Strong WR1; bankable weekly starter with spike-week ceiling. | O25: =INDEX('LIVE SOURCE'!$J$3:$J$232,$P25) -> Availability/sample risk is elevated after only 7 games; talent is not being punished as heavily as durability. | P25: =MATCH($A25,'Draft Engine'!$Q$3:$Q$232,0) -> 99
A26: =24 -> 24 | B26: =INDEX('Draft Engine'!$A$3:$A$232,$P26) -> RB | C26: =INDEX('Draft Engine'!$F$3:$F$232,$P26) -> 11 | D26: =INDEX('Draft Engine'!$B$3:$B$232,$P26) -> Breece Hall | E26: =INDEX('Draft Engine'!$E$3:$E$232,$P26) -> 85.8952 | F26: =IF($E26>=95,"ELITE",IF($E26>=90,"TIER 1",IF($E26>=85,"TIER 2",IF($E26>=80,"TIER 3",IF($E26>=75,"TIER 4",IF($E26>=70,"TIER 5",IF($E26>=65,"TIER 6","TIER 7"))))))) -> TIER 2 | G26: =INDEX('Draft Engine'!$G$3:$G$232,$P26) -> 290.8 | H26: =INDEX('Draft Engine'!$J$3:$J$232,$P26) -> 51.8 | I26: =INDEX('Draft Engine'!$N$3:$N$232,$P26) -> 85.22261 | J26: =INDEX('Draft Engine'!$R$3:$R$232,$P26) -> 27 | K26: =INDEX('Draft Engine'!$S$3:$S$232,$P26) -> 3 | L26: =INDEX('Draft Engine'!$T$3:$T$232,$P26) -> A | M26: =INDEX('Draft Engine'!$X$3:$X$232,$P26) -> RATE-ADJUSTED VETERAN | N26: =INDEX('LIVE SOURCE'!$H$3:$H$232,$P26) -> Strong RB1; weekly top-12 expectation with multi-touchdown ceiling. | O26: =INDEX('LIVE SOURCE'!$J$3:$J$232,$P26) -> Touchdown variance, receiving-role changes and backfield competition are the main downside paths. | P26: =MATCH($A26,'Draft Engine'!$Q$3:$Q$232,0) -> 43
A27: =25 -> 25 | B27: =INDEX('Draft Engine'!$A$3:$A$232,$P27) -> RB | C27: =INDEX('Draft Engine'!$F$3:$F$232,$P27) -> 12 | D27: =INDEX('Draft Engine'!$B$3:$B$232,$P27) -> Ashton Jeanty | E27: =INDEX('Draft Engine'!$E$3:$E$232,$P27) -> 85.8433 | F27: =IF($E27>=95,"ELITE",IF($E27>=90,"TIER 1",IF($E27>=85,"TIER 2",IF($E27>=80,"TIER 3",IF($E27>=75,"TIER 4",IF($E27>=70,"TIER 5",IF($E27>=65,"TIER 6","TIER 7"))))))) -> TIER 2 | G27: =INDEX('Draft Engine'!$G$3:$G$232,$P27) -> 290.5 | H27: =INDEX('Draft Engine'!$J$3:$J$232,$P27) -> 51.5 | I27: =INDEX('Draft Engine'!$N$3:$N$232,$P27) -> 84.78069 | J27: =INDEX('Draft Engine'!$R$3:$R$232,$P27) -> 13.8 | K27: =INDEX('Draft Engine'!$S$3:$S$232,$P27) -> -11.2 | L27: =INDEX('Draft Engine'!$T$3:$T$232,$P27) -> A | M27: =INDEX('Draft Engine'!$X$3:$X$232,$P27) -> RATE-ADJUSTED VETERAN | N27: =INDEX('LIVE SOURCE'!$H$3:$H$232,$P27) -> Strong RB1; weekly top-12 expectation with multi-touchdown ceiling. | O27: =INDEX('LIVE SOURCE'!$J$3:$J$232,$P27) -> Price is the biggest risk: the market currently asks you to draft him earlier than the model prefers. | P27: =MATCH($A27,'Draft Engine'!$Q$3:$Q$232,0) -> 44
A28: =26 -> 26 | B28: =INDEX('Draft Engine'!$A$3:$A$232,$P28) -> WR | C28: =INDEX('Draft Engine'!$F$3:$F$232,$P28) -> 11 | D28: =INDEX('Draft Engine'!$B$3:$B$232,$P28) -> CeeDee Lamb | E28: =INDEX('Draft Engine'!$E$3:$E$232,$P28) -> 85.7426 | F28: =IF($E28>=95,"ELITE",IF($E28>=90,"TIER 1",IF($E28>=85,"TIER 2",IF($E28>=80,"TIER 3",IF($E28>=75,"TIER 4",IF($E28>=70,"TIER 5",IF($E28>=65,"TIER 6","TIER 7"))))))) -> TIER 2 | G28: =INDEX('Draft Engine'!$G$3:$G$232,$P28) -> 290.1 | H28: =INDEX('Draft Engine'!$J$3:$J$232,$P28) -> 50.8 | I28: =INDEX('Draft Engine'!$N$3:$N$232,$P28) -> 84.469097 | J28: =INDEX('Draft Engine'!$R$3:$R$232,$P28) -> 11.2 | K28: =INDEX('Draft Engine'!$S$3:$S$232,$P28) -> -14.8 | L28: =INDEX('Draft Engine'!$T$3:$T$232,$P28) -> A | M28: =INDEX('Draft Engine'!$X$3:$X$232,$P28) -> HISTORY FALLBACK | N28: =INDEX('LIVE SOURCE'!$H$3:$H$232,$P28) -> Strong WR1; bankable weekly starter with spike-week ceiling. | O28: =INDEX('LIVE SOURCE'!$J$3:$J$232,$P28) -> Price is the biggest risk: the market currently asks you to draft him earlier than the model prefers. | P28: =MATCH($A28,'Draft Engine'!$Q$3:$Q$232,0) -> 90
A29: =27 -> 27 | B29: =INDEX('Draft Engine'!$A$3:$A$232,$P29) -> RB | C29: =INDEX('Draft Engine'!$F$3:$F$232,$P29) -> 13 | D29: =INDEX('Draft Engine'!$B$3:$B$232,$P29) -> Derrick Henry | E29: =INDEX('Draft Engine'!$E$3:$E$232,$P29) -> 85.6674 | F29: =IF($E29>=95,"ELITE",IF($E29>=90,"TIER 1",IF($E29>=85,"TIER 2",IF($E29>=80,"TIER 3",IF($E29>=75,"TIER 4",IF($E29>=70,"TIER 5",IF($E29>=65,"TIER 6","TIER 7"))))))) -> TIER 2 | G29: =INDEX('Draft Engine'!$G$3:$G$232,$P29) -> 289.8 | H29: =INDEX('Draft Engine'!$J$3:$J$232,$P29) -> 50.8 | I29: =INDEX('Draft Engine'!$N$3:$N$232,$P29) -> 84.19857 | J29: =INDEX('Draft Engine'!$R$3:$R$232,$P29) -> 15.4 | K29: =INDEX('Draft Engine'!$S$3:$S$232,$P29) -> -11.6 | L29: =INDEX('Draft Engine'!$T$3:$T$232,$P29) -> A | M29: =INDEX('Draft Engine'!$X$3:$X$232,$P29) -> RATE-ADJUSTED VETERAN | N29: =INDEX('LIVE SOURCE'!$H$3:$H$232,$P29) -> RB2 with RB1 weeks; should be a regular starter. | O29: =INDEX('LIVE SOURCE'!$J$3:$J$232,$P29) -> Touchdown variance, receiving-role changes and backfield competition are the main downside paths. | P29: =MATCH($A29,'Draft Engine'!$Q$3:$Q$232,0) -> 45
